<?xml version="1.0" encoding="UTF-8"?>
<testng-results skipped="1" failed="1" ignored="0" total="2" passed="0">
  <reporter-output>
  </reporter-output>
  <suite name="SeleniumOnlineProjectSuite" duration-ms="5044" started-at="2020-07-18T19:13:12 BDT" finished-at="2020-07-18T19:13:17 BDT">
    <groups>
    </groups>
    <test name="NewToursSiteTest" duration-ms="5044" started-at="2020-07-18T19:13:12 BDT" finished-at="2020-07-18T19:13:17 BDT">
      <class name="org.bitm.SeleniumOnlineProject.Test.LoginTest">
        <test-method status="FAIL" signature="checkLoginPageTitle()[pri:1, instance:org.bitm.SeleniumOnlineProject.Test.LoginTest@3a883ce7]" name="checkLoginPageTitle" duration-ms="5011" started-at="2020-07-18T19:13:12 BDT" finished-at="2020-07-18T19:13:17 BDT">
          <exception class="java.lang.AssertionError">
            <message>
              <![CDATA[expected [Welcome: Mercury Tours] but found [newtours.demoaut.com]]]>
            </message>
            <full-stacktrace>
              <![CDATA[java.lang.AssertionError: expected [Welcome: Mercury Tours] but found [newtours.demoaut.com]
at org.testng.Assert.fail(Assert.java:97)
at org.testng.Assert.assertEqualsImpl(Assert.java:136)
at org.testng.Assert.assertEquals(Assert.java:118)
at org.testng.Assert.assertEquals(Assert.java:575)
at org.testng.Assert.assertEquals(Assert.java:585)
at org.bitm.SeleniumOnlineProject.Test.LoginTest.checkLoginPageTitle(LoginTest.java:20)
at sun.reflect.NativeMethodAccessorImpl.invoke0(Native Method)
at sun.reflect.NativeMethodAccessorImpl.invoke(NativeMethodAccessorImpl.java:62)
at sun.reflect.DelegatingMethodAccessorImpl.invoke(DelegatingMethodAccessorImpl.java:43)
at java.lang.reflect.Method.invoke(Method.java:498)
at org.testng.internal.MethodInvocationHelper.invokeMethod(MethodInvocationHelper.java:135)
at org.testng.internal.TestInvoker.invokeMethod(TestInvoker.java:598)
at org.testng.internal.TestInvoker.invokeTestMethod(TestInvoker.java:174)
at org.testng.internal.MethodRunner.runInSequence(MethodRunner.java:46)
at org.testng.internal.TestInvoker$MethodInvocationAgent.invoke(TestInvoker.java:821)
at org.testng.internal.TestInvoker.invokeTestMethods(TestInvoker.java:147)
at org.testng.internal.TestMethodWorker.invokeTestMethods(TestMethodWorker.java:146)
at org.testng.internal.TestMethodWorker.run(TestMethodWorker.java:128)
at java.util.ArrayList.forEach(ArrayList.java:1257)
at org.testng.TestRunner.privateRun(TestRunner.java:767)
at org.testng.TestRunner.run(TestRunner.java:588)
at org.testng.SuiteRunner.runTest(SuiteRunner.java:384)
at org.testng.SuiteRunner.runSequentially(SuiteRunner.java:378)
at org.testng.SuiteRunner.privateRun(SuiteRunner.java:337)
at org.testng.SuiteRunner.run(SuiteRunner.java:286)
at org.testng.SuiteRunnerWorker.runSuite(SuiteRunnerWorker.java:53)
at org.testng.SuiteRunnerWorker.run(SuiteRunnerWorker.java:96)
at org.testng.TestNG.runSuitesSequentially(TestNG.java:1214)
at org.testng.TestNG.runSuitesLocally(TestNG.java:1136)
at org.testng.TestNG.runSuites(TestNG.java:1066)
at org.testng.TestNG.run(TestNG.java:1034)
at org.testng.remote.AbstractRemoteTestNG.run(AbstractRemoteTestNG.java:115)
at org.testng.remote.RemoteTestNG.initAndRun(RemoteTestNG.java:251)
at org.testng.remote.RemoteTestNG.main(RemoteTestNG.java:77)
]]>
            </full-stacktrace>
          </exception> <!-- java.lang.AssertionError -->
          <reporter-output>
          </reporter-output>
        </test-method> <!-- checkLoginPageTitle -->
        <test-method status="SKIP" signature="loginTest()[pri:0, instance:org.bitm.SeleniumOnlineProject.Test.LoginTest@3a883ce7]" name="loginTest" duration-ms="0" started-at="2020-07-18T19:13:17 BDT" depends-on-methods="org.bitm.SeleniumOnlineProject.Test.LoginTest.checkLoginPageTitle" finished-at="2020-07-18T19:13:17 BDT">
          <exception class="java.lang.Throwable">
            <message>
              <![CDATA[Method LoginTest.loginTest()[pri:0, instance:org.bitm.SeleniumOnlineProject.Test.LoginTest@3a883ce7] depends on not successfully finished methods]]>
            </message>
            <full-stacktrace>
              <![CDATA[java.lang.Throwable: Method LoginTest.loginTest()[pri:0, instance:org.bitm.SeleniumOnlineProject.Test.LoginTest@3a883ce7] depends on not successfully finished methods
at org.testng.internal.TestInvoker.invokeTestMethods(TestInvoker.java:102)
at org.testng.internal.TestMethodWorker.invokeTestMethods(TestMethodWorker.java:146)
at org.testng.internal.TestMethodWorker.run(TestMethodWorker.java:128)
at java.util.ArrayList.forEach(ArrayList.java:1257)
at org.testng.TestRunner.privateRun(TestRunner.java:767)
at org.testng.TestRunner.run(TestRunner.java:588)
at org.testng.SuiteRunner.runTest(SuiteRunner.java:384)
at org.testng.SuiteRunner.runSequentially(SuiteRunner.java:378)
at org.testng.SuiteRunner.privateRun(SuiteRunner.java:337)
at org.testng.SuiteRunner.run(SuiteRunner.java:286)
at org.testng.SuiteRunnerWorker.runSuite(SuiteRunnerWorker.java:53)
at org.testng.SuiteRunnerWorker.run(SuiteRunnerWorker.java:96)
at org.testng.TestNG.runSuitesSequentially(TestNG.java:1214)
at org.testng.TestNG.runSuitesLocally(TestNG.java:1136)
at org.testng.TestNG.runSuites(TestNG.java:1066)
at org.testng.TestNG.run(TestNG.java:1034)
at org.testng.remote.AbstractRemoteTestNG.run(AbstractRemoteTestNG.java:115)
at org.testng.remote.RemoteTestNG.initAndRun(RemoteTestNG.java:251)
at org.testng.remote.RemoteTestNG.main(RemoteTestNG.java:77)
]]>
            </full-stacktrace>
          </exception> <!-- java.lang.Throwable -->
          <reporter-output>
          </reporter-output>
        </test-method> <!-- loginTest -->
      </class> <!-- org.bitm.SeleniumOnlineProject.Test.LoginTest -->
    </test> <!-- NewToursSiteTest -->
  </suite> <!-- SeleniumOnlineProjectSuite -->
</testng-results>
